2024-02-29 14:26:28 INFO Retry attempt failed:
Traceback (most recent call last):
  File "D:\Envirenment\Anaconda\envs\pytorch\lib\site-packages\urllib3\connectionpool.py", line 712, in urlopen
    self._prepare_proxy(conn)
  File "D:\Envirenment\Anaconda\envs\pytorch\lib\site-packages\urllib3\connectionpool.py", line 1012, in _prepare_proxy
    conn.connect()
  File "D:\Envirenment\Anaconda\envs\pytorch\lib\site-packages\urllib3\connection.py", line 369, in connect
    self.sock = conn = self._connect_tls_proxy(hostname, conn)
  File "D:\Envirenment\Anaconda\envs\pytorch\lib\site-packages\urllib3\connection.py", line 504, in _connect_tls_proxy
    socket = ssl_wrap_socket(
  File "D:\Envirenment\Anaconda\envs\pytorch\lib\site-packages\urllib3\util\ssl_.py", line 453, in ssl_wrap_socket
    ssl_sock = _ssl_wrap_socket_impl(sock, context, tls_in_tls)
  File "D:\Envirenment\Anaconda\envs\pytorch\lib\site-packages\urllib3\util\ssl_.py", line 495, in _ssl_wrap_socket_impl
    return ssl_context.wrap_socket(sock)
  File "D:\Envirenment\Anaconda\envs\pytorch\lib\ssl.py", line 500, in wrap_socket
    return self.sslsocket_class._create(
  File "D:\Envirenment\Anaconda\envs\pytorch\lib\ssl.py", line 1073, in _create
    self.do_handshake()
  File "D:\Envirenment\Anaconda\envs\pytorch\lib\ssl.py", line 1342, in do_handshake
    self._sslobj.do_handshake()
ssl.SSLZeroReturnError: TLS/SSL connection has been closed (EOF) (_ssl.c:1131)

During handling of the above exception, another exception occurred:

Traceback (most recent call last):
  File "D:\Envirenment\Anaconda\envs\pytorch\lib\site-packages\requests\adapters.py", line 486, in send
    resp = conn.urlopen(
  File "D:\Envirenment\Anaconda\envs\pytorch\lib\site-packages\urllib3\connectionpool.py", line 799, in urlopen
    retries = retries.increment(
  File "D:\Envirenment\Anaconda\envs\pytorch\lib\site-packages\urllib3\util\retry.py", line 592, in increment
    raise MaxRetryError(_pool, url, error or ResponseError(cause))
urllib3.exceptions.MaxRetryError: HTTPSConnectionPool(host='api.wandb.ai', port=443): Max retries exceeded with url: /graphql (Caused by SSLError(SSLZeroReturnError(6, 'TLS/SSL connection has been closed (EOF) (_ssl.c:1131)')))

During handling of the above exception, another exception occurred:

Traceback (most recent call last):
  File "D:\Envirenment\Anaconda\envs\pytorch\lib\site-packages\wandb\sdk\lib\retry.py", line 131, in __call__
    result = self._call_fn(*args, **kwargs)
  File "D:\Envirenment\Anaconda\envs\pytorch\lib\site-packages\wandb\sdk\internal\internal_api.py", line 369, in execute
    return self.client.execute(*args, **kwargs)  # type: ignore
  File "D:\Envirenment\Anaconda\envs\pytorch\lib\site-packages\wandb\vendor\gql-0.2.0\wandb_gql\client.py", line 52, in execute
    result = self._get_result(document, *args, **kwargs)
  File "D:\Envirenment\Anaconda\envs\pytorch\lib\site-packages\wandb\vendor\gql-0.2.0\wandb_gql\client.py", line 60, in _get_result
    return self.transport.execute(document, *args, **kwargs)
  File "D:\Envirenment\Anaconda\envs\pytorch\lib\site-packages\wandb\sdk\lib\gql_request.py", line 58, in execute
    request = self.session.post(self.url, **post_args)
  File "D:\Envirenment\Anaconda\envs\pytorch\lib\site-packages\requests\sessions.py", line 637, in post
    return self.request("POST", url, data=data, json=json, **kwargs)
  File "D:\Envirenment\Anaconda\envs\pytorch\lib\site-packages\requests\sessions.py", line 589, in request
    resp = self.send(prep, **send_kwargs)
  File "D:\Envirenment\Anaconda\envs\pytorch\lib\site-packages\requests\sessions.py", line 703, in send
    r = adapter.send(request, **kwargs)
  File "D:\Envirenment\Anaconda\envs\pytorch\lib\site-packages\requests\adapters.py", line 517, in send
    raise SSLError(e, request=request)
requests.exceptions.SSLError: HTTPSConnectionPool(host='api.wandb.ai', port=443): Max retries exceeded with url: /graphql (Caused by SSLError(SSLZeroReturnError(6, 'TLS/SSL connection has been closed (EOF) (_ssl.c:1131)')))
2024-02-29 14:26:29 WARNING Retrying (Retry(total=2, connect=None, read=None, redirect=None, status=None)) after connection broken by 'SSLError(SSLZeroReturnError(6, 'TLS/SSL connection has been closed (EOF) (_ssl.c:1131)'))': /api/4504800232407040/envelope/
2024-02-29 14:26:30 WARNING Retrying (Retry(total=1, connect=None, read=None, redirect=None, status=None)) after connection broken by 'SSLError(SSLZeroReturnError(6, 'TLS/SSL connection has been closed (EOF) (_ssl.c:1131)'))': /api/4504800232407040/envelope/
2024-02-29 14:26:30 WARNING Retrying (Retry(total=0, connect=None, read=None, redirect=None, status=None)) after connection broken by 'SSLError(SSLZeroReturnError(6, 'TLS/SSL connection has been closed (EOF) (_ssl.c:1131)'))': /api/4504800232407040/envelope/
